const x = 10

try {
  
  x = 2
  console.log(x)

} catch (err) {
  console.log(`Erro: ${err}`)
}